Workbook

Sheet 2022-2023
A2: EMPLEADOS | C2: Vacaciones Pendientes (Dias Por Periodo) | G2: Dias Gozados Durante El Ejercicio (Dias-Periodo) | AA2: Total Días | AB2: Dias Pendientes
B3: Fecha De | AA3: Gozados | AB3: al 11 Nov-23
B4: Ingreso | E4: 2022 | F4: 2023 | G4: Dias | H4: Periodo | I4: Dias | J4: Periodo | K4: Dias | L4: Periodo | M4: Dias | N4: Periodo | O4: Dias | P4: Periodo | Q4: Dias | R4: Periodo | S4: Dias | T4: Periodo | U4: Dias | V4: Periodo | Y4: Dias | Z4: Periodo
A5: ALMA LIDIA GASTELUM HERNANDEZ | B5: 38598 | F5: 26 | G5: 1 | H5: 45003 | I5: 1 | J5: 45157 | K5: 18 | L5: 16-OCT-04-NOV | AA5: =G5+I5+K5+M5+O5+Q5+S5+Y5 -> 20 | AB5: =C5+D5+E5+F5-AA5 -> 6 | AC5: NOTA-CUANDO SE FUE DE VACACIONES SE LE PAGARON COMPLETAS EN CASO DE OCUPAR LOS DIAS VA SER PERMISO SIN GOSE DE SUELDO
A6: HILDA BEATRIZ BELTRAN LOPEZ | B6: 41276 | E6: 12 | F6: 22 | G6: 0.5 | H6: ENE | I6: 2.5 | J6: FEB | K6: 1.5 | L6: MAR | M6: 7 | N6: 21-MAR-01-ABR | O6: 0.5 | P6: 45079 | Q6: 0.5 | R6: JUN | S6: 3 | T6: 7-8-10-JUL | U6: 1 | V6: AGO | W6: 0.5 | X6: 45199 | Y6: 0.5 | Z6: 45217 | AA6: =G6+I6+K6+M6+O6+Q6+S6+U6+W6+Y6 -> 17.5 | AB6: =C6+D6+E6+F6-AA6 -> 16.5
A7: ANA MARIA SUAREZ PALOMARES | B7: 42247 | E7: 14 | F7: 22 | G7: 3 | H7: 12-13-23-ENE | I7: 1 | J7: 45003 | K7: 1 | L7: 45105 | M7: 1 | N7: 45115 | O7: 8 | P7: 01-09-SEP | Q7: 1 | R7: 45180 | AA7: =G7+I7+K7+M7+O7+Q7+S7+U7+W7+Y7 -> 15 | AB7: =C7+D7+E7+F7-AA7 -> 21
A8: MISAEL VELAZQUEZ GUERRERO | B8: 41730 | F8: 22 | G8: 2 | H8: 10-11 ABR | I8: 6 | J8: 17-22-JUL | AA8: =G8+I8+K8+M8+O8+Q8+S8+Y8 -> 8 | AB8: =C8+D8+E8+F8-AA8 -> 14
A9: JOSE ALFREDO VALVERDE TOLOSA | B9: 42006 | E9: 9 | F9: 22 | G9: 0.5 | H9: 44973 | I9: 0.5 | J9: 45016 | K9: 1 | L9: 45017 | M9: 1 | N9: 45094 | O9: 7 | P9: 45136 | AA9: =G9+I9+K9+M9+O9+Q9+S9+Y9 -> 10 | AB9: =C9+D9+E9+F9-AA9 -> 21
A10: MARIA MAGDALENA GARCIA LEON | B10: 42633 | F10: 22 | G10: 18 | H10: 1-19-AGO | I10: 1.5 | J10: 7-08-NOV | AA10: =G10+I10+K10+M10+O10+Q10+S10+Y10 -> 19.5 | AB10: =C10+D10+E10+F10-AA10 -> 2.5
A11: ALICIA ISABEL SICAIROS AGUIRRE | B11: 44771 | F11: 12 | G11: 0.5 | H11: 45035 | I11: 1 | J11: 45057 | K11: 7 | L11: 26-AGO-02-SEP | M11: 1 | N11: 45229 | O11: 2.5 | P11: 09-11-NOV | AA11: =G11+I11+K11+M11+O11+Q11+S11+Y11 -> 12 | AB11: =C11+D11+E11+F11-AA11 -> 0
A12: MARIA CRISTINA BARRAZA VIZCARRA | B12: 42646 | E12: 13 | F12: 22 | G12: 6 | H12: 03-08-ABR | I12: 6 | J12: 03/08-JUL | K12: 1 | L12: 45132 | M12: 1 | N12: 45216 | O12: 1 | P12: 30-NOV-PAGADO | AA12: =G12+I12+K12+M12+O12+Q12+S12+Y12 -> 15 | AB12: =C12+D12+E12+F12-AA12 -> 20
A13: AMERICA NATHALY VEGA GONZALEZ | B13: 43381 | E13: 12 | F13: 20 | G13: 3 | H13: 19-20-23-ENE | I13: 1 | J13: 45029 | K13: 1 | L13: 45163 | M13: 0.5 | N13: 45187 | O13: 2.5 | P13: 22-25-SEP | Q13: 3 | R13: 23-25-SEP | S13: 1 | T13: SE PAGO 30-NOV | V13: PERIODO 2022 | AA13: =G13+I13+K13+M13+O13+Q13+S13+Y13 -> 12 | AB13: =C13+D13+E13+F13-AA13 -> 20
A14: YUKIE LIZETH PACHECO RAMIREZ | B14: 43850 | F14: 16 | G14: 5 | H14: 07-11-FEB | I14: 1 | J14: 45073 | K14: 0.5 | L14: 45087 | M14: 0.5 | N14: 45108 | O14: 7 | P14: 02-09-SEP | Q14: 1 | R14: 45227 | AA14: =G14+I14+K14+M14+O14+Q14+S14+Y14 -> 15 | AB14: =C14+D14+E14+F14-AA14 -> 1
A15: MAURA LIZETH BERNAL LOPEZ | B15: 44690 | F15: 12 | G15: 0.5 | H15: 45009 | I15: 0.5 | J15: 45121 | K15: 6 | L15: 24-29-JUL | M15: 1 | N15: 45157 | O15: 0.5 | P15: 45211 | AA15: =G15+I15+K15+M15+O15+Q15+S15+Y15 -> 8.5 | AB15: =C15+D15+E15+F15-AA15 -> 3.5
A16: JOSE VALDEMAR CORVERA CARDENAS | B16: 44669 | F16: 12 | G16: 1 | H16: 45003 | I16: 1 | J16: 45031 | K16: 1 | L16: 45051 | M16: 1 | N16: 45127 | O16: 4 | P16: 02-17-18-19-AGO | Q16: 1 | R16: 45226 | AA16: =G16+I16+K16+M16+O16+Q16+S16+Y16 -> 9 | AB16: =C16+D16+E16+F16-AA16 -> 3
A17: LIZBETH GUADALUPE GALAZ RIVERA | B17: 44893 | F17: 12 | G17: 2 | H17: 24-25-AGO | AA17: =G17+I17+K17+M17+O17+Q17+S17+Y17 -> 2 | AB17: =C17+D17+E17+F17-AA17 -> 10
A18: FRANCISCO JAVIER AYALA HERNANDEZ | B18: 45160 | AA18: =G18+I18+K18+M18+O18+Q18+S18+Y18 -> 0 | AB18: =C18+D18+E18+F18-AA18 -> 0
A19: JUAN CARLOS PACHECO PEREZ | B19: 44700 | F19: 12 | G19: 1 | H19: 45057 | I19: 6 | J19: 29-MAY-03-JUN | AA19: =G19+I19+K19+M19+O19+Q19+S19+Y19 -> 7 | AB19: =C19+D19+E19+F19-AA19 -> 5
A20: BRAYAN URIEL ANGULO RAMIREZ | B20: 44805 | F20: 12 | AA20: =G20+I20+K20+M20+O20+Q20+S20+Y20 -> 0 | AB20: =C20+D20+E20+F20-AA20 -> 12
A21: PEDRO IVAN BELTRAN URIARTE | B21: 41730 | E21: 14 | F21: 22 | G21: 8 | H21: 10-18-FEB | I21: 6 | J21: 10-15-ABR | K21: 1 | L21: 45092 | M21: 9 | N21: 07-16-AGO | AA21: =G21+I21+K21+M21+O21+Q21+S21+Y21 -> 24 | AB21: =C21+D21+E21+F21-AA21 -> 12
A22: JOSE GUADALUPE GARCIA CANCHOLA | B22: 43913 | F22: 16 | G22: 16 | H22: 15-MAR-PAGARON | AA22: =G22+I22+K22+M22+O22+Q22+S22+Y22 -> 16 | AB22: =C22+D22+E22+F22-AA22 -> 0
A23: JOSE AGUSTIN MENDOZA SEPULVEDA | B23: 44578 | F23: 12 | G23: 12 | H23: 31-ENE-PAGARON | AA23: =G23+I23+K23+M23+O23+Q23+S23+Y23 -> 12 | AB23: =C23+D23+E23+F23-AA23 -> 0
A24: ANGEL GERARDO LOPEZ FLORES | B24: 44277 | F24: 14 | G24: 3 | H24: 21-23-MAR | I24: 7 | J24: 01-08-ABRI | K24: 4 | L24: 24-27-JUL | AA24: =G24+I24+K24+M24+O24+Q24+S24+Y24 -> 14 | AB24: =C24+D24+E24+F24-AA24 -> 0
A25: MARIO ALBERTO VARGAS HERNANDEZ | B25: 44279 | F25: 14 | G25: 6 | H25: 03-08-ABR | AA25: =G25+I25+K25+M25+O25+Q25+S25+Y25 -> 6 | AB25: =C25+D25+E25+F25-AA25 -> 8
A26: LLUVIA DE JESUS ROMERO SARABIA | B26: 44293 | F26: 14 | G26: 1 | H26: 45038 | I26: 6 | J26: 23-29-MAY | K26: 1 | L26: 45121 | M26: 1 | N26: 45201 | AA26: =G26+I26+K26+M26+O26+Q26+S26+Y26 -> 9 | AB26: =C26+D26+E26+F26-AA26 -> 5
A27: EDGAR SAUL FRAGA MELCHOR | B27: 44908 | F27: 12 | AA27: =G27+I27+K27+M27+O27+Q27+S27+Y27 -> 0 | AB27: =C27+D27+E27+F27-AA27 -> 12
A28: JULIO CESAR ARAUJO | B28: 44805 | F28: 12 | G28: 12 | H28: 15-SEP-PAGARON | AA28: =G28+I28+K28+M28+O28+Q28+S28+Y28 -> 12 | AB28: =C28+D28+E28+F28-AA28 -> 0
A29: JORGE ENRIQUE ARELLANES CHAVEZ | B29: 44805 | F29: 12 | AA29: =G29+I29+K29+M29+O29+Q29+S29+Y29 -> 0 | AB29: =C29+D29+E29+F29-AA29 -> 12
A30: ANTONY MEDRANO LOPEZ | B30: 44866 | F30: 12 | AA30: =G30+I30+K30+M30+O30+Q30+S30+Y30 -> 0 | AB30: =C30+D30+E30+F30-AA30 -> 12
A31: JOSEFINA DE JESUS RAMOS ACOSTA | B31: 45077 | AA31: =G31+I31+K31+M31+O31+Q31+S31+Y31 -> 0 | AB31: =C31+D31+E31+F31-AA31 -> 0
A32: ELISA GUADALUPE GARCIA GONZALEZ | B32: 45185 | AA32: =G32+I32+K32+M32+O32+Q32+S32+Y32 -> 0 | AB32: =C32+D32+E32+F32-AA32 -> 0
A33: OSCAR VICENTE VALDEZ BURGUEÑO | B33: 42627 | F33: 22 | G33: 1 | H33: 45066 | AA33: =G33+I33+K33+M33+O33+Q33+S33+Y33 -> 1 | AB33: =C33+D33+E33+F33-AA33 -> 21
A34: ANTONIO NUÑEZ RAMOS | B34: 44957 | F34: 12 | AA34: =G34+I34+K34+M34+O34+Q34+S34+Y34 -> 0 | AB34: =C34+D34+E34+F34-AA34 -> 12
A35: LUIS ALFREDO RODRIGEZ VALVERDE | B35: 45170 | AA35: =G35+I35+K35+M35+O35+Q35+S35+Y35 -> 0 | AB35: =C35+D35+E35+F35-AA35 -> 0
A36: JANETH JOSEFINA GONZALEZ ROSALES | B36: 44608 | F36: 12 | G36: 2 | H36: 09-28-MAR | I36: 2 | J36: 05-26-JUL | K36: 1.5 | L36: 24-28-JUL | M36: 1 | N36: 45180 | O36: 1 | P36: 45219 | Q36: 1 | R36: 45236 | AA36: =G36+I36+K36+M36+O36+Q36+S36+Y36 -> 8.5 | AB36: =C36+D36+E36+F36-AA36 -> 3.5
A37: JACQUELINE GUADALUPE IRIARTE FELIX | B37: 43612 | F37: 18 | G37: 4 | H37: 14-17-ABR | I37: 1 | J37: 45066 | K37: 1 | L37: 45094 | M37: 9 | N37: 15-25-JUL | O37: 0.5 | P37: 45156 | AA37: =G37+I37+K37+M37+O37+Q37+S37+Y37 -> 15.5 | AB37: =C37+D37+E37+F37-AA37 -> 2.5
A38: JHENIFER BARRAZA LOPEZ | B38: 43481 | F38: 18 | G38: 1.5 | H38: 26-27-JUL | I38: 5 | J38: 13-19-SEP | K38: 2 | L38: 28-29-SEP | AA38: =G38+I38+K38+M38+O38+Q38+S38+Y38 -> 8.5 | AB38: =C38+D38+E38+F38-AA38 -> 9.5
A39: GUADALUPE LEYVA ARAUJO | B39: 44292 | F39: 14 | G39: 1 | H39: 44980 | I39: 1 | J39: 45052 | K39: 0.5 | L39: 45075 | M39: 6 | N39: 18-25-NOV | AA39: =G39+I39+K39+M39+O39+Q39+S39+Y39 -> 8.5 | AB39: =C39+D39+E39+F39-AA39 -> 5.5
A40: MARITZA LOPEZ LOPEZ | B40: 44743 | F40: 12 | G40: 1 | H40: 45236 | I40: 1 | J40: 09-10-NOV | AA40: =G40+I40+K40+M40+O40+Q40+S40+Y40 -> 2 | AB40: =C40+D40+E40+F40-AA40 -> 10
A41: JESSICA TIRADO ZAMUDIO | B41: 44889 | F41: 12 | G41: 1 | H41: 45180 | AA41: =G41+I41+K41+M41+O41+Q41+S41+Y41 -> 1 | AB41: =C41+D41+E41+F41-AA41 -> 11
...

Sheet 2023
C1: DIAS
A2: EMPLEADOS | C2: Vacaciones | D2: Dias Gozados Durante El Ejercicio (Dias-Periodo) | V2: Total Días | W2: Dias
B3: Fecha De | V3: Gozados | W3: Pendientes
B4: Ingreso | C4: 2023 | D4: Dias | E4: Periodo | F4: Dias | G4: Periodo | H4: Dias | I4: Periodo | J4: Dias | K4: Periodo | L4: Dias | M4: Periodo | N4: Dias | O4: Periodo | P4: Dias | Q4: Periodo | R4: Dias | S4: Periodo | T4: Dias | U4: Periodo | W4: al 11 Nov-23
A5: ALMA LIDIA GASTELUM HERNANDEZ | B5: 38598 | C5: 26 | D5: 1 | E5: 45003 | F5: 1 | G5: 45157 | H5: 18 | I5: 16-OCT-04-NOV | V5: =D5+F5+H5+J5+L5+N5+P5+R5+T5 -> 20 | W5: =C5-V5 -> 6 | X5: NOTA-CUANDO SE FUE DE VACACIONES SE LE PAGARON COMPLETAS EN CASO DE OCUPAR LOS DIAS VA SER PERMISO SIN GOSE DE SUELDO
A6: HILDA BEATRIZ BELTRAN LOPEZ | B6: 41276 | C6: 22 | D6: 0.5 | E6: JUN | F6: 3 | G6: 7-8-10-JUL | H6: 1 | I6: AGO | J6: 0.5 | K6: 45199 | L6: 0.5 | M6: 45217 | V6: =D6+F6+H6+J6+L6+N6+P6+R6+T6 -> 5.5 | W6: =C6-V6 -> 16.5
A7: ANA MARIA SUAREZ PALOMARES | B7: 42247 | C7: 22 | D7: 1 | E7: 45180 | F7: 0.5 | G7: 45287 | V7: =D7+F7+H7+J7+L7+N7+P7+R7+T7 -> 1.5 | W7: =C7-V7 -> 20.5
A8: MISAEL VELAZQUEZ GUERRERO | B8: 41730 | C8: 22 | D8: 2 | E8: 10-11 ABR | F8: 6 | G8: 17-22-JUL | H8: 14 | I8: SE PAGO 30-NOV | V8: =D8+F8+H8+J8+L8+N8+P8+R8+T8 -> 22 | W8: =C8-V8 -> 0
A9: JOSE ALFREDO VALVERDE TOLOSA | B9: 42006 | C9: 22 | D9: 1 | E9: 45136 | F9: 1.5 | G9: 29-30-DIC | V9: =D9+F9+H9+J9+L9+N9+P9+R9+T9 -> 2.5 | W9: =C9-V9 -> 19.5
A10: MARIA MAGDALENA GARCIA LEON | B10: 42633 | C10: 22 | D10: 18 | E10: 1-19-AGO | F10: 1.5 | G10: 7-08-NOV | H10: 0.5 | I10: 45251 | J10: 0.5 | K10: 45281 | V10: =D10+F10+H10+J10+L10+N10+P10+R10+T10 -> 20.5 | W10: =C10-V10 -> 1.5
A11: ALICIA ISABEL SICAIROS AGUIRRE | B11: 44771 | C11: 12 | D11: 0.5 | E11: 45035 | F11: 1 | G11: 45057 | H11: 7 | I11: 26-AGO-02-SEP | J11: 1 | K11: 45229 | L11: 2.5 | M11: 09-11-NOV | V11: =D11+F11+H11+J11+L11+N11+P11+R11+T11 -> 12 | W11: =C11-V11 -> 0
A12: MARIA CRISTINA BARRAZA VIZCARRA | B12: 42646 | C12: 22 | D12: 1 | E12: 45216 | V12: =D12+F12+H12+J12+L12+N12+P12+R12+T12 -> 1 | W12: =C12-V12 -> 21
A13: AMERICA NATHALY VEGA GONZALEZ | B13: 43381 | C13: 20 | V13: =D13+F13+H13+J13+L13+N13+P13+R13+T13 -> 0 | W13: =C13-V13 -> 20
A14: YUKIE LIZETH PACHECO RAMIREZ | B14: 43850 | C14: 16 | D14: 5 | E14: 07-11-FEB | F14: 1 | G14: 45073 | H14: 0.5 | I14: 45087 | J14: 0.5 | K14: 45108 | L14: 7 | M14: 02-09-SEP | N14: 1 | O14: 45227 | P14: 1 | Q14: SE PAGO-30-NOV | V14: =D14+F14+H14+J14+L14+N14+P14+R14+T14 -> 16 | W14: =C14-V14 -> 0
A15: MAURA LIZETH BERNAL LOPEZ | B15: 44690 | C15: 12 | D15: 0.5 | E15: 45009 | F15: 0.5 | G15: 45121 | H15: 6 | I15: 24-29-JUL | J15: 1 | K15: 45157 | L15: 0.5 | M15: 45211 | N15: 0.5 | O15: 45246 | P15: 3 | Q15: 24 AL 27 NOV | V15: =D15+F15+H15+J15+L15+N15+P15+R15+T15 -> 12 | W15: =C15-V15 -> 0
A16: JOSE VALDEMAR CORVERA CARDENAS | B16: 44669 | C16: 12 | D16: 1 | E16: 45003 | F16: 1 | G16: 45031 | H16: 1 | I16: 45051 | J16: 1 | K16: 45127 | L16: 4 | M16: 02-17-18-19-AGO | N16: 1 | O16: 45225 | P16: 1 | Q16: 45260 | R16: 1 | S16: 45272 | V16: =D16+F16+H16+J16+L16+N16+P16+R16+T16 -> 11 | W16: =C16-V16 -> 1
A17: LIZBETH GUADALUPE GALAZ RIVERA | B17: 44893 | C17: 12 | D17: 2 | E17: 24-25-AGO | F17: 1 | G17: 45258 | V17: =D17+F17+H17+J17+L17+N17+P17+R17+T17 -> 3 | W17: =C17-V17 -> 9
A18: FRANCISCO JAVIER AYALA HERNANDEZ | B18: 45160 | V18: =D18+F18+H18+J18+L18+N18+P18+R18+T18 -> 0 | W18: =C18-V18 -> 0
A19: JUAN CARLOS PACHECO PEREZ | B19: 44700 | C19: 12 | D19: 1 | E19: 45057 | F19: 6 | G19: 29-MAY-03-JUN | H19: 1 | I19: 45281 | J19: 4 | K19: PAGO PRIMA Y RESTO DE DIAS | V19: =D19+F19+H19+J19+L19+N19+P19+R19+T19 -> 12 | W19: =C19-V19 -> 0
A20: BRAYAN URIEL ANGULO RAMIREZ | B20: 44805 | C20: 12 | D20: 2 | E20: 21-22-NOV | F20: 1 | G20: 45278 | V20: =D20+F20+H20+J20+L20+N20+P20+R20+T20 -> 3 | W20: =C20-V20 -> 9
A21: PEDRO IVAN BELTRAN URIARTE | B21: 41730 | C21: 22 | D21: 1 | E21: 45092 | F21: 9 | G21: 07-16-AGO | H21: 2 | I21: 22-23-DIC | J21: 10 | K21: PAGO PRIMA Y RESTO DE DIAS | V21: =D21+F21+H21+J21+L21+N21+P21+R21+T21 -> 22 | W21: =C21-V21 -> 0
A22: JOSE GUADALUPE GARCIA CANCHOLA | B22: 43913 | C22: 16 | D22: 16 | E22: 15-MAR-PAGARON | V22: =D22+F22+H22+J22+L22+N22+P22+R22+T22 -> 16 | W22: =C22-V22 -> 0
A23: JOSE AGUSTIN MENDOZA SEPULVEDA | B23: 44578 | C23: 12 | D23: 12 | E23: 31-ENE-PAGARON | V23: =D23+F23+H23+J23+L23+N23+P23+R23+T23 -> 12 | W23: =C23-V23 -> 0
A24: ANGEL GERARDO LOPEZ FLORES | B24: 44277 | C24: 14 | D24: 3 | E24: 21-23-MAR | F24: 7 | G24: 01-08-ABRI | H24: 4 | I24: 24-27-JUL | V24: =D24+F24+H24+J24+L24+N24+P24+R24+T24 -> 14 | W24: =C24-V24 -> 0
A25: MARIO ALBERTO VARGAS HERNANDEZ | B25: 44279 | C25: 14 | D25: 6 | E25: 03-08-ABR | F25: 8 | G25: 04 AL 12 DIC | V25: =D25+F25+H25+J25+L25+N25+P25+R25+T25 -> 14 | W25: =C25-V25 -> 0
A26: LLUVIA DE JESUS ROMERO SARABIA | B26: 44293 | C26: 14 | D26: 1 | E26: 45038 | F26: 6 | G26: 23-29-MAY | H26: 1 | I26: 45121 | J26: 1 | K26: 45201 | L26: 5 | M26: 21 AL 25-NOV | V26: =D26+F26+H26+J26+L26+N26+P26+R26+T26 -> 14 | W26: =C26-V26 -> 0
A27: EDGAR SAUL FRAGA MELCHOR | B27: 44908 | C27: 12 | D27: 1 | E27: 45653 | F27: 2 | G27: 02-03-ENE-2024 | V27: =D27+F27+H27+J27+L27+N27+P27+R27+T27 -> 3 | W27: =C27-V27 -> 9
A28: JULIO CESAR ARAUJO | B28: 44805 | C28: 12 | D28: 12 | E28: 15-SEP-PAGARON | V28: =D28+F28+H28+J28+L28+N28+P28+R28+T28 -> 12 | W28: =C28-V28 -> 0
A29: JORGE ENRIQUE ARELLANES CHAVEZ | B29: 44805 | C29: 12 | V29: =D29+F29+H29+J29+L29+N29+P29+R29+T29 -> 0 | W29: =C29-V29 -> 12
A30: ANTONY MEDRANO LOPEZ | B30: 44866 | C30: 12 | D30: 3 | E30: 25-29-30-NOV | F30: 1 | G30: 45271 | V30: =D30+F30+H30+J30+L30+N30+P30+R30+T30 -> 4 | W30: =C30-V30 -> 8
A31: JOSEFINA DE JESUS RAMOS ACOSTA | B31: 45077 | V31: =D31+F31+H31+J31+L31+N31+P31+R31+T31 -> 0 | W31: =C31-V31 -> 0
A32: ELISA GUADALUPE GARCIA GONZALEZ | B32: 45185 | V32: =D32+F32+H32+J32+L32+N32+P32+R32+T32 -> 0 | W32: =C32-V32 -> 0
A33: OSCAR VICENTE VALDEZ BURGUEÑO | B33: 42627 | C33: 36 | D33: 1 | E33: 45066 | F33: 13 | G33: 30-DIC-PAGARON | I33: PERIODO 2021-2022 | K33: TOCAN 14 DIAS | V33: =D33+F33+H33+J33+L33+N33+P33+R33+T33 -> 14 | W33: =C33-V33 -> 22
A34: ANTONIO NUÑEZ RAMOS | B34: 44957 | C34: 12 | V34: =D34+F34+H34+J34+L34+N34+P34+R34+T34 -> 0 | W34: =C34-V34 -> 12
A35: LUIS ALFREDO RODRIGEZ VALVERDE | B35: 45170 | V35: =D35+F35+H35+J35+L35+N35+P35+R35+T35 -> 0 | W35: =C35-V35 -> 0
A36: JANETH JOSEFINA GONZALEZ ROSALES | B36: 44608 | C36: 12 | D36: 2 | E36: 09-28-MAR | F36: 2 | G36: 05-26-JUL | H36: 1.5 | I36: 24-28-JUL | J36: 1 | K36: 45180 | L36: 1 | M36: 45219 | N36: 1 | O36: 45236 | P36: 1 | Q36: 45255 | R36: 1.5 | S36: 07-28-DIC | T36: 1 | U36: PAGO 15-FEB | V36: =D36+F36+H36+J36+L36+N36+P36+R36+T36 -> 12 | W36: =C36-V36 -> 0
A37: JACQUELINE GUADALUPE IRIARTE FELIX | B37: 43612 | C37: 18 | D37: 4 | E37: 14-17-ABR | F37: 1 | G37: 45066 | H37: 1 | I37: 45094 | J37: 9 | K37: 15-25-JUL | L37: 0.5 | M37: 45156 | N37: 0.5 | O37: 45244 | P37: 1 | Q37: 45245 | R37: 0.5 | S37: 45247 | T37: 0.5 | U37: 45253 | V37: =D37+F37+H37+J37+L37+N37+P37+R37+T37 -> 18 | W37: =C37-V37 -> 0
A38: JHENIFER BARRAZA LOPEZ | B38: 43481 | C38: 18 | D38: 1.5 | E38: 26-27-JUL | F38: 5 | G38: 13-19-SEP | H38: 2 | I38: 28-29-SEP | J38: 9.5 | K38: SE PAGO 30-NOV | V38: =D38+F38+H38+J38+L38+N38+P38+R38+T38 -> 18 | W38: =C38-V38 -> 0
A39: GUADALUPE LEYVA ARAUJO | B39: 44292 | C39: 14 | D39: 1 | E39: 44980 | F39: 1 | G39: 45052 | H39: 0.5 | I39: 45075 | J39: 6 | K39: 18-25-NOV | L39: 5.5 | M39: SE PAGO 30-NOV | V39: =D39+F39+H39+J39+L39+N39+P39+R39+T39 -> 14 | W39: =C39-V39 -> 0
A40: MARITZA LOPEZ LOPEZ | B40: 44743 | C40: 12 | D40: 1 | E40: 45236 | F40: 1 | G40: 09-10-NOV | H40: 10 | I40: SE PAGO 30-NOV | V40: =D40+F40+H40+J40+L40+N40+P40+R40+T40 -> 12 | W40: =C40-V40 -> 0
...

Sheet 2024
D1: DIAS
A2: EMPLEADOS | D2: Vacaciones | E2: Dias Gozados Durante El Ejercicio (Dias-Periodo) | U2: Total Días | V2: Dias
B3: Fecha De | U3: Gozados | V3: Pendientes
B4: Ingreso | C4: 2023 | D4: 2024 | E4: Dias | F4: Periodo | G4: Dias | H4: Periodo | I4: Dias | J4: Periodo | K4: Dias | L4: Periodo | M4: Dias | N4: Periodo | O4: Dias | P4: Periodo | Q4: Dias | R4: Periodo | S4: Dias | T4: Periodo | V4: al 17 Ene-24
A5: ALMA LIDIA GASTELUM HERNANDEZ | B5: 38598 | C5: 0 | D5: 26 | F5: VACACIONES PAGADAS 15-AGO-2024 | U5: =E5+G5+I5+K5+M5+O5+Q5+S5 -> 0 | V5: =C5+D5-U5 -> 26
A6: HILDA BEATRIZ BELTRAN LOPEZ | B6: 41276 | C6: 22 | D6: 24 | E6: 0.5 | F6: JUN | G6: 3 | H6: 7-8-10-JUL | I6: 1.5 | J6: 03-ago-30-sep | K6: 0.5 | L6: 45583 | M6: 16.5 | N6: 30-17 FEB | O6: 2 | P6: 10-30-ABR | Q6: 13 | R6: 45517 | S6: 3 | T6: 45605 | U6: =E6+G6+I6+K6+M6+O6+Q6+S6 -> 40 | V6: =C6+D6-U6 -> 6
A7: ANA MARIA SUAREZ PALOMARES | B7: 42247 | C7: 22 | D7: 22 | E7: 1 | F7: 45180 | G7: 0.5 | H7: 45287 | I7: 5 | J7: 06-10-FEB | K7: 1 | L7: 45419 | M7: 1 | N7: 45498 | O7: 9 | P7: 45558 | Q7: 1.5 | R7: 45618 | S7: 3 | T7: 21-DIC-PAGADOS | U7: =E7+G7+I7+K7+M7+O7+Q7+S7 -> 22 | V7: =C7+D7-U7 -> 22
A8: MISAEL VELAZQUEZ GUERRERO | B8: 41730 | C8: ='2023'!W8 -> 0 | D8: 22 | E8: 1 | F8: 45383 | G8: 1 | H8: 45405 | I8: 1 | J8: 45467 | K8: 6 | L8: 22 AL 27 JUL | M8: 1 | N8: 45535 | O8: 12 | P8: 45640 | U8: =E8+G8+I8+K8+M8+O8+Q8+S8 -> 22 | V8: =C8+D8-U8 -> 0
A9: JOSE ALFREDO VALVERDE TOLOSA | B9: 42006 | C9: 22 | D9: 22 | E9: 1 | F9: 45136 | G9: 1.5 | H9: 29-30-DIC | I9: 1 | J9: 45353 | K9: 0.5 | L9: 45387 | M9: 1 | N9: 45409 | O9: 0.5 | P9: 45464 | Q9: 1.5 | R9: 05-06-JUL | S9: 7.5 | T9: 02-AL 10 AGO | U9: =E9+G9+I9+K9+M9+O9+Q9+S9 -> 14.5 | V9: =C9+D9-U9 -> 29.5
A10: MARIA MAGDALENA GARCIA LEON | B10: 42633 | C10: 22 | D10: 22 | E10: 18 | F10: 1-19-AGO | G10: 2 | H10: 7-08-21-NOV | I10: 0.5 | J10: 45647 | K10: 0.5 | L10: 45315 | M10: 0.5 | N10: 45317 | O10: 0.5 | P10: 45418 | Q10: 1 | R10: 29-JUN-05-JUL | S10: 18 | T10: 45537 | U10: =E10+G10+I10+K10+M10+O10+Q10+S10 -> 41 | V10: =C10+D10-U10 -> 3
A11: ALICIA ISABEL SICAIROS AGUIRRE | B11: 44771 | C11: ='2023'!W11 -> 0 | D11: 14 | E11: 0.5 | F11: 45476 | G11: 6 | H11: 29 AL 03 AGO | I11: 0.5 | J11: 45589 | K11: 7 | L11: 45607 | U11: =E11+G11+I11+K11+M11+O11+Q11+S11 -> 14 | V11: =C11+D11-U11 -> 0
A12: MARIA CRISTINA BARRAZA VIZCARRA | B12: 42646 | C12: 22 | D12: 22 | E12: 1 | F12: 45216 | G12: 1 | H12: 45426 | I12: 1 | J12: 45447 | K12: 1 | L12: 45538 | M12: 8 | N12: 45615 | O12: 10 | P12: PAGADOS | Q12: 1 | R12: 45629 | U12: =E12+G12+I12+K12+M12+O12+Q12+S12 -> 23 | V12: =C12+D12-U12 -> 21
A13: AMERICA NATHALY VEGA GONZALEZ | B13: 43381 | C13: ='2023'!W13 -> 20 | D13: 22 | E13: 5 | F13: 01 AL 05 ABR | G13: 1 | H13: 45467 | I13: 7 | J13: 07 AL 14 OCT | K13: 7 | L13: 45580 | M13: 0.5 | N13: 45653 | U13: =E13+G13+I13+K13+M13+O13+Q13+S13 -> 20.5 | V13: =C13+D13-U13 -> 21.5
A14: YUKIE LIZETH PACHECO RAMIREZ | B14: 43850 | C14: ='2023'!W14 -> 0 | D14: 18 | E14: 6 | F14: 19 AL 25 MAR | G14: 1 | H14: 45453 | I14: 11 | J14: 45593 | U14: =E14+G14+I14+K14+M14+O14+Q14+S14 -> 18 | V14: =C14+D14-U14 -> 0
A15: MAURA LIZETH BERNAL LOPEZ | B15: 44690 | C15: ='2023'!W15 -> 0 | D15: 14 | E15: 1 | F15: 45306 | G15: 0.5 | H15: 45376 | I15: 1 | J15: 45428 | K15: 7 | L15: 45542 | M15: 0.5 | N15: 361.12 | U15: =E15+G15+I15+K15+M15+O15+Q15+S15 -> 10 | V15: =C15+D15-U15 -> 4
A16: JOSE VALDEMAR CORVERA CARDENAS | B16: 44669 | C16: 0 | D16: 14 | E16: 1 | F16: 45356 | G16: 1 | H16: 45409 | I16: 1 | J16: 45429 | K16: 4 | L16: 19-22-JUN | M16: 3 | N16: 12-13-15-JUL | O16: 1 | P16: 45535 | Q16: 1 | R16: 45561 | S16: 1 | T16: 45591 | U16: =E16+G16+I16+K16+M16+O16+Q16+S16 -> 13 | V16: =C16+D16-U16 -> 1
A17: JESUS ALBERTO MORGAN CHAVEZ | B17: 45463 | D17: 12 | U17: =E17+G17+I17+K17+M17+O17+Q17+S17 -> 0 | V17: =C17+D17-U17 -> 12
A18: GLORIA GISELLE ALVAREZ HERNANDEZ | B18: 45467 | D18: 12 | E18: 1 | F18: 45596 | G18: 1 | H18: 45597 | I18: 1 | J18: 45598 | U18: =E18+G18+I18+K18+M18+O18+Q18+S18 -> 3 | V18: =C18+D18-U18 -> 9
A19: JUAN CARLOS PACHECO PEREZ | B19: 44700 | C19: ='2023'!W19 -> 0 | D19: 14 | E19: 1 | F19: 45463 | G19: 1 | H19: 45490 | I19: 1 | J19: 45544 | K19: 1 | L19: 45559 | M19: 1 | N19: 45569 | O19: 1 | P19: 45632 | Q19: 1 | R19: 45664 | U19: =E19+G19+I19+K19+M19+O19+Q19+S19 -> 7 | V19: =C19+D19-U19 -> 7
A20: BRAYAN URIEL ANGULO RAMIREZ | B20: 44805 | C20: 12 | D20: 14 | E20: 2 | F20: 21-22-NOV | G20: 1 | H20: 45278 | I20: 1 | J20: 45330 | K20: 1 | L20: 45412 | M20: 2 | N20: 18-30-MAY | O20: 5 | P20: 45442 | Q20: 1 | R20: 45579 | S20: 13 | T20: PAGARON | U20: =E20+G20+I20+K20+M20+O20+Q20+S20 -> 26 | V20: =C20+D20-U20 -> 0
A21: ORLANDO RAMON VALDEZ GARCIA | U21: =E21+G21+I21+K21+M21+O21+Q21+S21 -> 0 | V21: =C21+D21-U21 -> 0
A22: JOSE GUADALUPE GARCIA CANCHOLA | B22: 43913 | C22: ='2023'!W22 -> 0 | D22: 18 | E22: 4 | F22: 15 AL 19 MAR | H22: 31-MAR PAGO RESTO | U22: =E22+G22+I22+K22+M22+O22+Q22+S22 -> 4 | V22: =C22+D22-U22 -> 14
A23: JOSE AGUSTIN MENDOZA SEPULVEDA | B23: 44578 | C23: ='2023'!W23 -> 0 | D23: 14 | E23: 14 | F23: VACACIONES PAGADAS 31-ENE-2024 | U23: =E23+G23+I23+K23+M23+O23+Q23+S23 -> 14 | V23: =C23+D23-U23 -> 0
A24: ANGEL GERARDO LOPEZ FLORES | B24: 44277 | C24: ='2023'!W24 -> 0 | D24: 16 | E24: 1 | F24: 45308 | G24: 1 | H24: 45316 | I24: 1 | J24: 45381 | K24: 2 | L24: 11-13-MAY | M24: 1 | N24: 45458 | O24: 7 | P24: 03 al 10 AGO | Q24: 1 | R24: 45570 | S24: 1 | T24: 45629 | U24: =E24+G24+I24+K24+M24+O24+Q24+S24 -> 15 | V24: =C24+D24-U24 -> 1
A25: MARIO ALBERTO VARGAS HERNANDEZ | B25: 44279 | C25: ='2023'!W25 -> 0 | D25: 16 | E25: 12 | F25: 15 AL 27 JUL | U25: =E25+G25+I25+K25+M25+O25+Q25+S25 -> 12 | V25: =C25+D25-U25 -> 4
A26: LLUVIA DE JESUS ROMERO SARABIA | B26: 44293 | C26: ='2023'!W26 -> 0 | D26: 16 | E26: 2 | F26: 13-25-MAR | G26: 3 | H26: 03-09-23-ABR | I26: 3 | J26: 06-17-25-MAY | K26: 1 | L26: 45454 | M26: 3 | N26: 45513 | O26: 1 | P26: 45583 | Q26: 0.5 | R26: 45615 | S26: 1 | T26: 45664 | U26: =E26+G26+I26+K26+M26+O26+Q26+S26 -> 14.5 | V26: =C26+D26-U26 -> 1.5
A27: EDGAR SAUL FRAGA MELCHOR | B27: 44908 | C27: 12 | E27: 1 | F27: 45653 | G27: 2 | H27: 02-03-ENE-2024 | I27: 2 | J27: 10-12-FEB | K27: 1 | L27: 45352 | U27: =E27+G27+I27+K27+M27+O27+Q27+S27 -> 6 | V27: =C27+D27-U27 -> 6
A28: JULIO CESAR ARAUJO | B28: 44805 | C28: ='2023'!W28 -> 0 | D28: 14 | U28: =E28+G28+I28+K28+M28+O28+Q28+S28 -> 0 | V28: =C28+D28-U28 -> 14
A29: JORGE ENRIQUE ARELLANES CHAVEZ | B29: 44805 | C29: ='2023'!W29 -> 12 | D29: 14 | E29: 5 | F29: 29-E-AL-02-FEB | U29: =E29+G29+I29+K29+M29+O29+Q29+S29 -> 5 | V29: =C29+D29-U29 -> 21
A30: ANTONY MEDRANO LOPEZ | B30: 44866 | C30: 12 | E30: 3 | F30: 25-29-30-NOV | G30: 1 | H30: 45271 | I30: 2 | J30: 07-14-FEB | K30: 1 | L30: 45418 | M30: 1 | N30: 45482 | O30: 1 | P30: 45640 | U30: =E30+G30+I30+K30+M30+O30+Q30+S30 -> 9 | V30: =C30+D30-U30 -> 3
A31: ELISA GUADALUPE GARCIA GONZALEZ | B31: 45185 | C31: ='2023'!W32 -> 0 | D31: 12 | E31: 1 | F31: 45535 | G31: 1 | H31: 45577 | I31: 1 | J31: 45626 | K31: 1 | L31: 45645 | U31: =E31+G31+I31+K31+M31+O31+Q31+S31 -> 4 | V31: =C31+D31-U31 -> 8
A32: ISAURO FELIPE RIVERA ACOSTA | B32: 45231 | D32: 12 | E32: 1 | F32: 45554 | G32: 1 | H32: 45653 | I32: 2 | J32: 30-31-DIC | U32: =E32+G32+I32+K32+M32+O32+Q32+S32 -> 4 | V32: =C32+D32-U32 -> 8
A33: MARIA FERNANDA RODRIGUEZ ARMENTA | B33: 45451
A34: CLAUDIA LIZBETH JUAREZ LOPEZ | B34: 45593
A35: OSCAR VICENTE VALDEZ BURGUEÑO | B35: 42627 | C35: ='2023'!W33 -> 22 | D35: 22 | G35: 6 | H35: 22 AL 27 JUL | U35: =E35+G35+I35+K35+M35+O35+Q35+S35 -> 6 | V35: =C35+D35-U35 -> 38
A36: ANTONIO NUÑEZ RAMOS | B36: 44957 | D36: 12 | E36: 6 | F36: 45523 | H36: RESTO DE DIAS SE LIQUIDO | U36: =E36+G36+I36+K36+M36+O36+Q36+S36 -> 6 | V36: =C36+D36-U36 -> 6
A37: MARIO ALBERTO OCHOA CASTAÑEDA | B37: 45549 | U37: =E37+G37+I37+K37+M37+O37+Q37+S37 -> 0 | V37: =C37+D37-U37 -> 0
A38: JANETH JOSEFINA GONZALEZ ROSALES | B38: 44608 | C38: =12-12 -> 0 | D38: 14 | E38: 1 | F38: 45344 | G38: 2 | H38: 13-22-MAR | I38: 2 | J38: 45399 | K38: 1 | L38: 45419 | M38: 1 | N38: 45475 | O38: 3 | P38: 45530 | Q38: 1 | R38: 45583 | S38: 1 | T38: 45609 | U38: =E38+G38+I38+K38+M38+O38+Q38+S38 -> 12 | V38: =C38+D38-U38 -> 2
A39: JACQUELINE GUADALUPE IRIARTE FELIX | B39: 43612 | C39: ='2023'!W37 -> 0 | D39: 20 | E39: 1 | F39: 45355 | G39: 0.5 | H39: 45372 | I39: 1 | J39: 45402 | K39: 1 | L39: 45455 | M39: 8 | N39: 05 AL 13 JUL | O39: 3 | P39: 45526 | Q39: 2 | R39: 15-23-OCT | S39: 0.5 | T39: 45617 | U39: =E39+G39+I39+K39+M39+O39+Q39+S39 -> 17 | V39: =C39+D39-U39 -> 3
A40: JHENIFER BARRAZA LOPEZ | B40: 43481 | C40: ='2023'!W38 -> 0 | D40: 20 | E40: 0.5 | F40: 45352 | G40: 0.5 | H40: 45447 | I40: 0.5 | J40: 45448 | K40: 0.5 | L40: 45474 | M40: 15 | N40: 26 AL 12 AGO | O40: 2 | P40: 45615 | U40: =E40+G40+I40+K40+M40+O40+Q40+S40 -> 19 | V40: =C40+D40-U40 -> 1
...

Sheet 2025
D1: DIAS
A2: EMPLEADOS | D2: Vacaciones | F2: Dias Gozados Durante El Ejercicio (Dias-Periodo) | AP2: Dias | AQ2: Dias
B3: Fecha De | AP3: Gozados | AQ3: Pendientes
B4: Ingreso | C4: 2023 | D4: 2024 | E4: 2025 | F4: Dias | G4: Periodo | H4: Dias | I4: Periodo | J4: Dias | K4: Periodo | L4: Dias | M4: Periodo | N4: Dias | O4: Periodo | P4: Dias | Q4: Periodo | R4: Dias | S4: Periodo | T4: Dias | U4: Periodo | AQ4: al 17 Ene-24
A5: ALMA LIDIA GASTELUM HERNANDEZ | B5: 38717 | E5: 26 | F5: 3 | G5: 21 AL 24 FEB | H5: 2 | I5: 18-19-ABR | J5: 21 | K5: 10 SEP AL 04 OCT | AP5: =F5+H5+J5+L5+N5+P5+R5+T5+V5+X5+Z5+AB5+AD5+AF5+AH5+AJ5+AL5+AN5 -> 26 | AQ5: =C5+D5+E5-AP5 -> 0
A6: HILDA BEATRIZ BELTRAN LOPEZ | B6: 41276 | D6: 24 | E6: 24 | F6: 2 | G6: 10-30-ABR | H6: 13 | I6: 45517 | J6: 3 | K6: 45605 | L6: 6 | M6: 22 AL 28 ABR | N6: 0.5 | O6: 45825 | P6: 0.5 | Q6: 45827 | R6: 0.5 | S6: 45840 | T6: 0.5 | U6: 45860 | V6: 13 | W6: 01 AL 15 SEP | X6: 0.5 | Y6: 45929 | Z6: 3 | AA6: 10 al 12 NOV | AB6: 1 | AC6: 46018 | AD6: 4.5 | AE6: PAGADOS-31-DIC | AP6: =F6+H6+J6+L6+N6+P6+R6+T6+V6+X6+Z6+AB6+AD6+AF6+AH6+AJ6+AL6+AN6 -> 48 | AQ6: =C6+D6+E6-AP6 -> 0
A7: ANA MARIA SUAREZ PALOMARES | B7: 42247 | D7: 22 | E7: 22 | F7: 0.5 | G7: 45685 | H7: 0.5 | I7: 45720 | J7: 1 | K7: 45731 | L7: 1 | M7: 45734 | N7: 0.5 | O7: 45754 | P7: 2 | Q7: 18-19-ABR | R7: 0.5 | S7: 45770 | T7: 0.5 | U7: 45771 | V7: 0.5 | W7: 45790 | X7: 0.5 | Y7: 45827 | Z7: 0.5 | AA7: 45856 | AB7: 14 | AC7: 28 al 12 AGO | AD7: 0.5 | AE7: 45887 | AF7: 0.5 | AG7: 45918 | AH7: 0.5 | AI7: 45946 | AJ7: 1 | AK7: 45976 | AL7: 0.5 | AM7: 45979 | AN7: 0.5 | AO7: 46008 | AP7: =F7+H7+J7+L7+N7+P7+R7+T7+V7+X7+Z7+AB7+AD7+AF7+AH7+AJ7+AL7+AN7 -> 25.5 | AQ7: =C7+D7+E7-AP7 -> 18.5
A8: MISAEL VELAZQUEZ GUERRERO | B8: 41730 | E8: 24 | F8: 2 | G8: 01-04-FEB | H8: 3 | I8: 18-19-21-ABR | J8: 0.5 | K8: 45818 | L8: 1 | M8: 45829 | N8: 0.5 | O8: 45841 | P8: 1 | Q8: 45915 | R8: 1 | S8: 45990 | T8: 15 | U8: PAGADOS-15-DIC | AP8: =F8+H8+J8+L8+N8+P8+R8+T8+V8+X8+Z8+AB8+AD8+AF8+AH8+AJ8+AL8+AN8 -> 24 | AQ8: =C8+D8+E8-AP8 -> 0
A9: JOSE ALFREDO VALVERDE TOLOSA | B9: 42006 | E9: 12 | F9: 1 | G9: 45689 | H9: 1 | I9: 45724 | J9: 0.5 | K9: 45758 | L9: 2 | M9: 02-03-MAY | N9: 0.5 | O9: 45826 | P9: 5 | Q9: 45853 | R9: 0.5 | S9: 45883 | T9: 0.5 | U9: 45896 | AP9: =F9+H9+J9+L9+N9+P9+R9+T9+V9+X9+Z9+AB9+AD9+AF9+AH9+AJ9+AL9+AN9 -> 11 | AQ9: =C9+D9+E9-AP9 -> 1
A10: MARIA MAGDALENA GARCIA LEON | B10: 42633 | D10: 22 | E10: 22 | F10: 18 | G10: 02 AL 23 SEP | H10: 0.5 | I10: 45721 | J10: 2 | K10: 18-19-ABR | L10: 1.5 | N10: 18 | O10: 01 AL 21 AGO | P10: 0.5 | Q10: 45960 | AP10: =F10+H10+J10+L10+N10+P10+R10+T10+V10+X10+Z10+AB10+AD10+AF10+AH10+AJ10+AL10+AN10 -> 40.5 | AQ10: =C10+D10+E10-AP10 -> 3.5
A11: ALICIA ISABEL SICAIROS AGUIRRE | B11: 44771 | E11: 16 | F11: 0.5 | G11: 45715 | H11: 0.5 | I11: 45756 | J11: 1 | K11: 45764 | L11: 0.5 | M11: 45805 | N11: 0.5 | O11: 45826 | P11: 0.5 | Q11: 45829 | R11: 0.5 | S11: 45869 | T11: 1 | U11: 45902 | V11: 4 | W11: 03 AL 06 SEP | X11: 7 | Y11: 09 AL 16 OCT | AP11: =F11+H11+J11+L11+N11+P11+R11+T11+V11+X11+Z11+AB11+AD11+AF11+AH11+AJ11+AL11+AN11 -> 16 | AQ11: =C11+D11+E11-AP11 -> 0
A12: MARIA CRISTINA BARRAZA VIZCARRA | B12: 42646 | D12: 22 | E12: 22 | F12: 1 | G12: 45994 | H12: 1 | I12: 45755 | J12: 2 | K12: 18-19-ABR | L12: 1 | M12: 45793 | N12: 1 | O12: 45835 | P12: 13 | Q12: 01 AL 15 SEP | R12: 3 | S12: PAGARON 15-SEP | T12: 2 | U12: 26-27-NOV | V12: 3 | W12: 08-09-10-DIC | X12: 3 | Y12: 15-16-17-DIC | AP12: =F12+H12+J12+L12+N12+P12+R12+T12+V12+X12+Z12+AB12+AD12+AF12+AH12+AJ12+AL12+AN12 -> 30 | AQ12: =C12+D12+E12-AP12 -> 14
A13: AMERICA NATHALY VEGA GONZALEZ | B13: 43381 | D13: 22 | E13: 22 | F13: 0.5 | G13: 46018 | H13: 2 | I13: 24-25-FEB | J13: 0.5 | K13: 45744 | L13: 1 | M13: 45777 | N13: 1 | O13: 45779 | P13: 1 | Q13: 45829 | R13: 5 | S13: 14 AL 18 JUL | T13: 1 | U13: 45934 | V13: 9 | W13: 13 al 24 NOV | X13: 1 | Y13: 45989 | AP13: =F13+H13+J13+L13+N13+P13+R13+T13+V13+X13+Z13+AB13+AD13+AF13+AH13+AJ13+AL13+AN13 -> 22 | AQ13: =C13+D13+E13-AP13 -> 22
A14: YUKIE LIZETH PACHECO RAMIREZ | B14: 43850 | E14: 20 | F14: 12 | G14: 17FEB AL 01MAR | H14: 1 | I14: 45724 | J14: 2 | K14: 18-19-ABR | L14: 5 | M14: 29 SEP AL 03 OCT | AP14: =F14+H14+J14+L14+N14+P14+R14+T14+V14+X14+Z14+AB14+AD14+AF14+AH14+AJ14+AL14+AN14 -> 20 | AQ14: =C14+D14+E14-AP14 -> 0
A15: LUIS ROBERTO BELTRAN OJEDA | B15: 45605 | E15: 12 | AP15: =F15+H15+J15+L15+N15+P15+R15+T15+V15+X15+Z15+AB15+AD15+AF15+AH15+AJ15+AL15+AN15 -> 0 | AQ15: =C15+D15+E15-AP15 -> 12
A16: MAURA LIZETH BERNAL LOPEZ | B16: 44690 | D16: 14 | E16: 16 | F16: 1 | G16: 45306 | H16: 0.5 | I16: 45376 | J16: 1 | K16: 45428 | L16: 1 | N16: 7 | O16: 45542 | P16: 0.5 | Q16: 361.12 | R16: 1 | S16: 45743 | T16: 2 | U16: 18-19-ABR | V16: 1 | W16: 45819 | AP16: =F16+H16+J16+L16+N16+P16+R16+T16+V16+X16+Z16+AB16+AD16+AF16+AH16+AJ16+AL16+AN16 -> 15 | AQ16: =C16+D16+E16-AP16 -> 15
A17: JOSE VALDEMAR CORVERA CARDENAS | B17: 44669 | E17: 16 | F17: 1 | G17: 45673 | H17: 1 | I17: 45714 | J17: 1 | K17: 45758 | L17: 2 | M17: 18-19-ABR | N17: 1 | O17: 45784 | P17: 4 | Q17: 18 al 21 JUN | R17: 1 | S17: 45843 | T17: 1 | U17: 45862 | V17: 2 | W17: 13-15-SEP | X17: 2 | Y17: 05-06-NOV | Z17: 1 | AA17: 46008 | AP17: =F17+H17+J17+L17+N17+P17+R17+T17+V17+X17+Z17+AB17+AD17+AF17+AH17+AJ17+AL17+AN17 -> 17 | AQ17: =C17+D17+E17-AP17 -> -1
A18: JESUS ALBERTO MORGAN CHAVEZ | B18: 45463 | E18: 12 | F18: 2 | G18: 18-19-ABR | H18: 1 | I18: 45825 | J18: 0.5 | K18: 45840 | L18: 0.5 | M18: 45841 | N18: 3 | O18: 05-07-08-JUL | P18: 1 | Q18: 45917 | R18: 1 | S18: 46008 | AP18: =F18+H18+J18+L18+N18+P18+R18+T18+V18+X18+Z18+AB18+AD18+AF18+AH18+AJ18+AL18+AN18 -> 9 | AQ18: =C18+D18+E18-AP18 -> 3
A19: GRECIA CARRANZA MARTINEZ | B19: 45827 | F19: 1 | G19: 45919 | AP19: =F19+H19+J19+L19+N19+P19+R19+T19+V19+X19+Z19+AB19+AD19+AF19+AH19+AJ19+AL19+AN19 -> 1 | AQ19: =C19+D19+E19-AP19 -> -1
A20: JUAN CARLOS PACHECO PEREZ | B20: 44700 | D20: 14 | E20: 16 | F20: 1 | G20: 45463 | H20: 1 | I20: 45490 | J20: 2 | K20: 09-24-SEP | L20: 1 | M20: 45569 | N20: 1 | O20: 45632 | P20: 1 | Q20: 45664 | R20: 1 | S20: 45702 | T20: 2 | U20: 24-25-FEB | V20: 4 | W20: PAGADOS | X20: 1 | Y20: 45756 | Z20: 1 | AA20: 45794 | AB20: 1 | AC20: 45838 | AD20: 1 | AE20: 45847 | AF20: 1 | AG20: 45871 | AH20: 1 | AI20: 45926 | AJ20: 2 | AK20: 25-27-OCT | AL20: 1 | AM20: 45975 | AN20: 1 | AO20: 46000 | AP20: =F20+H20+J20+L20+N20+P20+R20+T20+V20+X20+Z20+AB20+AD20+AF20+AH20+AJ20+AL20+AN20 -> 24 | AQ20: =C20+D20+E20-AP20 -> 6
A21: BRAYAN URIEL ANGULO RAMIREZ | B21: 44805 | E21: 16 | F21: 1 | G21: 45687 | H21: 1 | I21: 45891 | J21: 1 | K21: 45958 | L21: 3 | M21: 31 OCT AL 03 NOV | N21: 0.5 | O21: 45986 | AP21: =F21+H21+J21+L21+N21+P21+R21+T21+V21+X21+Z21+AB21+AD21+AF21+AH21+AJ21+AL21+AN21 -> 6.5 | AQ21: =C21+D21+E21-AP21 -> 9.5
A22: ORLANDO RAMON VALDEZ GARCIA | B22: 45521 | E22: 12 | F22: 0.5 | G22: 45685 | H22: 1 | I22: 45706 | J22: 1 | K22: 45748 | L22: 1 | M22: 45779 | N22: 1 | O22: 45861 | P22: 5 | Q22: DEL 25 AL 29 AGO | R22: 1 | S22: 45901 | T22: 1 | U22: 45927 | AP22: =F22+H22+J22+L22+N22+P22+R22+T22+V22+X22+Z22+AB22+AD22+AF22+AH22+AJ22+AL22+AN22 -> 11.5 | AQ22: =C22+D22+E22-AP22 -> 0.5
A23: JOSE GUADALUPE GARCIA CANCHOLA | B23: 43913 | E23: 20 | F23: 20 | G23: VACACIONES PAGADAS 15-JUL-2025 | AP23: =F23+H23+J23+L23+N23+P23+R23+T23+V23+X23+Z23+AB23+AD23+AF23+AH23+AJ23+AL23+AN23 -> 20 | AQ23: =C23+D23+E23-AP23 -> 0
A24: JOSE AGUSTIN MENDOZA SEPULVEDA | B24: 44578 | E24: 16 | F24: 16 | G24: VACACIONES PAGADAS 15-ENE-2025 | J24: 1 | K24: 45765 | AP24: =F24+H24+J24+L24+N24+P24+R24+T24+V24+X24+Z24+AB24+AD24+AF24+AH24+AJ24+AL24+AN24 -> 17 | AQ24: =C24+D24+E24-AP24 -> -1
A25: ANGEL GERARDO LOPEZ FLORES | B25: 44277 | D25: 16 | E25: 18 | F25: 2 | G25: 17-25-ENE | H25: 1 | I25: 45746 | J25: 2 | K25: 11-13-MAY | L25: 1 | M25: 45823 | N25: 7 | O25: 03 al 10 AGO | P25: 1 | Q25: 45935 | R25: 1 | S25: 45994 | T25: 1 | U25: 45692 | V25: 1 | W25: 45745 | X25: 4 | Y25: 18 AL 22 ABR | Z25: 2 | AA25: 25-26-JUN | AB25: 1 | AC25: 45845 | AD25: 1 | AE25: 45859 | AF25: 1 | AG25: 45877 | AH25: 2 | AI25: 16-18-AGO | AJ25: 2 | AK25: 23-25-AGO | AL25: 4 | AM25: 12 al 15 NOV | AP25: =F25+H25+J25+L25+N25+P25+R25+T25+V25+X25+Z25+AB25+AD25+AF25+AH25+AJ25+AL25+AN25 -> 34 | AQ25: =C25+D25+E25-AP25 -> 0
A26: LLUVIA DE JESUS ROMERO SARABIA | B26: 44293 | D26: 16 | E26: 18 | F26: 2 | G26: 13-25-MAR | H26: 3 | I26: 03-09-23-ABR | J26: 2 | K26: 17-25-MAY | L26: 1 | M26: 45454 | N26: 3 | O26: 45513 | P26: 1 | Q26: 45583 | R26: 0.5 | S26: 45615 | T26: 1 | U26: 45664 | V26: 1 | W26: 45694 | X26: 2.5 | Y26: 05-10-12-mar | Z26: 2 | AA26: 18-19-ABR | AB26: 1 | AC26: 45782 | AD26: 1 | AE26: 45839 | AF26: 1 | AG26: 45859 | AH26: 2 | AI26: 01-02-SEP | AJ26: 1 | AK26: 45964 | AP26: =F26+H26+J26+L26+N26+P26+R26+T26+V26+X26+Z26+AB26+AD26+AF26+AH26+AJ26+AL26+AN26 -> 25 | AQ26: =C26+D26+E26-AP26 -> 9
A27: JULIO CESAR ARAUJO | B27: 44805 | E27: 16 | F27: 3 | G27: 19-20-21-MAY | H27: 1 | I27: 45912 | J27: 2 | K27: 26-27-SEP | AP27: =F27+H27+J27+L27+N27+P27+R27+T27+V27+X27+Z27+AB27+AD27+AF27+AH27+AJ27+AL27+AN27 -> 6 | AQ27: =C27+D27+E27-AP27 -> 10
A28: JORGE ENRIQUE ARELLANES CHAVEZ | B28: 44805 | C28: 12 | D28: 14 | E28: 16 | F28: 5 | G28: 29-E-AL-02-FEB | H28: 7 | I28: 01 al 08 mar | J28: 1 | K28: 45765 | L28: 13 | M28: PAGADOS 15-DIC | AP28: =F28+H28+J28+L28+N28+P28+R28+T28+V28+X28+Z28+AB28+AD28+AF28+AH28+AJ28+AL28+AN28 -> 26 | AQ28: =C28+D28+E28-AP28 -> 16
A29: ANTONY MEDRANO LOPEZ | B29: 44866 | C29: 12 | D29: 14 | F29: 3 | G29: 25-29-30-NOV | H29: 1 | I29: 45271 | J29: 2 | K29: 07-14-FEB | L29: 1 | M29: 45418 | N29: 1 | O29: 45482 | P29: 1 | Q29: 45640 | R29: 1 | S29: 45752 | T29: 2 | U29: 18-19-ABR | V29: 1 | W29: 45847 | X29: 1 | Y29: 45880 | Z29: 1 | AA29: 45881 | AB29: 2 | AC29: 05-06-SEP | AD29: 2 | AE29: 12-13-SEP | AF29: 2 | AG29: 29-30-SEP | AH29: 1 | AI29: 45931 | AJ29: 1 | AK29: 45951 | AL29: 1 | AM29: 45969 | AN29: 1 | AO29: 45992 | AP29: =F29+H29+J29+L29+N29+P29+R29+T29+V29+X29+Z29+AB29+AD29+AF29+AH29+AJ29+AL29+AN29 -> 25 | AQ29: =C29+D29+E29-AP29 -> 1
A30: ELISA GUADALUPE GARCIA GONZALEZ | B30: 45185 | D30: 12 | E30: 14 | F30: 1 | G30: 45535 | H30: 1 | I30: 45577 | J30: 1 | K30: 45626 | L30: 1 | M30: 45645 | N30: 1 | O30: 45696 | P30: 2 | Q30: 08-13-mar | R30: 1 | S30: 45752 | T30: 2 | U30: 18-19-ABR | V30: 1 | W30: 45832 | X30: 1 | Y30: 45913 | Z30: 1 | AA30: 45960 | AB30: 1 | AC30: 45967 | AD30: 1 | AE30: 45969 | AP30: =F30+H30+J30+L30+N30+P30+R30+T30+V30+X30+Z30+AB30+AD30+AF30+AH30+AJ30+AL30+AN30 -> 15 | AQ30: =C30+D30+E30-AP30 -> 11
A31: ISAURO FELIPE RIVERA ACOSTA | B31: 45231 | D31: 12 | F31: 1 | G31: 45554 | H31: 1 | I31: 45653 | J31: 2 | K31: 30-31-DIC | L31: 2 | M31: 22-24-FEB | N31: 1 | O31: 45776 | P31: 1 | Q31: 45787 | R31: 1 | S31: 45864 | T31: 0.5 | U31: 45868 | V31: 0.5 | W31: 45889 | X31: 7 | Y31: 23 AL 30 SEP | Z31: 1 | AA31: 45945 | AB31: 4 | AP31: =F31+H31+J31+L31+N31+P31+R31+T31+V31+X31+Z31+AB31+AD31+AF31+AH31+AJ31+AL31+AN31 -> 22 | AQ31: =C31+D31+E31-AP31 -> -10
A32: ISABEL SAENZ LEON | B32: 45287 | D32: 12 | F32: 1 | G32: 45765 | H32: 1 | I32: 45780 | J32: 1 | K32: 45885 | AP32: =F32+H32+J32+L32+N32+P32+R32+T32+V32+X32+Z32+AB32+AD32+AF32+AH32+AJ32+AL32+AN32 -> 3 | AQ32: =C32+D32+E32-AP32 -> 9
A33: MARIA FERNANDA RODRIGUEZ ARMENTA | B33: 45451 | E33: 12 | F33: 2 | G33: 18-19-ABR | H33: 1 | I33: 45853 | J33: 4 | K33: 06 AL 09 AGO | L33: 1 | M33: 45883 | N33: 1 | O33: 45952 | AP33: =F33+H33+J33+L33+N33+P33+R33+T33+V33+X33+Z33+AB33+AD33+AF33+AH33+AJ33+AL33+AN33 -> 9 | AQ33: =C33+D33+E33-AP33 -> 3
A34: CLAUDIA LIZBETH JUAREZ LOPEZ | B34: 45593 | E34: 12 | F34: 2 | G34: 18-19-ABR | H34: 1 | I34: 45869 | J34: 1 | K34: 45945 | L34: 1 | M34: 45972 | N34: 1 | O34: 45992 | AP34: =F34+H34+J34+L34+N34+P34+R34+T34+V34+X34+Z34+AB34+AD34+AF34+AH34+AJ34+AL34+AN34 -> 6 | AQ34: =C34+D34+E34-AP34 -> 6
A35: JESUS EDUARDO BELTRAN LOPEZ | B35: 45622 | E35: 12 | F35: 2 | G35: 18-19-ABR | H35: 1 | I35: 45773 | J35: 0.5 | K35: 45786 | L35: 0.5 | M35: 45828 | N35: 1 | O35: 45908 | AP35: =F35+H35+J35+L35+N35+P35+R35+T35+V35+X35+Z35+AB35+AD35+AF35+AH35+AJ35+AL35+AN35 -> 5 | AQ35: =C35+D35+E35-AP35 -> 7
A36: OSCAR VICENTE VALDEZ BURGUEÑO | B36: 42627 | D36: 22 | F36: 2 | G36: 07-08-FEB | H36: 2 | I36: 18-19-JUL | J36: 18 | K36: PAGADAS | AP36: =F36+H36+J36+L36+N36+P36+R36+T36+V36+X36+Z36+AB36+AD36+AF36+AH36+AJ36+AL36+AN36 -> 22 | AQ36: =C36+D36+E36-AP36 -> 0
A37: ANTONIO NUÑEZ RAMOS | B37: 44957 | E37: 14 | F37: 1 | G37: 45773 | H37: 13 | I37: 17 SEP AL 01 OCT | AP37: =F37+H37+J37+L37+N37+P37+R37+T37+V37+X37+Z37+AB37+AD37+AF37+AH37+AJ37+AL37+AN37 -> 14 | AQ37: =C37+D37+E37-AP37 -> 0
A38: MARIO ALBERTO OCHOA CASTAÑEDA | B38: 45549 | E38: 12 | F38: 12 | G38: 01 AL 14 NOV | AP38: =F38+H38+J38+L38+N38+P38+R38+T38+V38+X38+Z38+AB38+AD38+AF38+AH38+AJ38+AL38+AN38 -> 12 | AQ38: =C38+D38+E38-AP38 -> 0
A39: JANETH JOSEFINA GONZALEZ ROSALES | B39: 44608 | E39: 16 | F39: 1 | G39: 45723 | H39: 1 | I39: 45742 | J39: 2.5 | K39: 17-18-19-ABR | L39: 3 | M39: 24-25-26-JUN | N39: 1.5 | O39: 16-18-AGO | P39: 1 | Q39: 45894 | R39: 6 | S39: 01 AL 06 SEP | T39: 1 | U39: 46008 | V39: 1 | W39: 46018 | AP39: =F39+H39+J39+L39+N39+P39+R39+T39+V39+X39+Z39+AB39+AD39+AF39+AH39+AJ39+AL39+AN39 -> 18 | AQ39: =C39+D39+E39-AP39 -> -2
A40: JHENIFER BARRAZA LOPEZ | B40: 43481 | E40: 22 | F40: 4 | G40: 19 AL 22 FEB | H40: 6 | I40: 21 AL 26 JUL | J40: 0.5 | K40: 45961 | L40: 6 | M40: 03 al 08 NOV | N40: 0.5 | O40: 45981 | P40: 0.5 | Q40: 46001 | R40: 0.5 | S40: 46008 | T40: 0.5 | U40: 46017 | V40: 3.5 | W40: PAGADOS-31-DIC | AP40: =F40+H40+J40+L40+N40+P40+R40+T40+V40+X40+Z40+AB40+AD40+AF40+AH40+AJ40+AL40+AN40 -> 22 | AQ40: =C40+D40+E40-AP40 -> 0
...

Sheet 2026
A1: EMPLEADOS | C1: Dias Vacaciones | F1: Dias Gozados Durante El Ejercicio (Dias-Periodo) | AP1: Dias | AQ1: Dias
B2: Fecha De | AP2: Gozados | AQ2: Pendientes
B3: Ingreso | C3: 2024 | D3: 2025 | E3: 2026 | F3: Dias | G3: Periodo | H3: Dias | I3: Periodo | J3: Dias | K3: Periodo | L3: Dias | M3: Periodo | N3: Dias | O3: Periodo | P3: Dias | Q3: Periodo | R3: Dias | S3: Periodo | T3: Dias | U3: Periodo | AQ3: al 14 Abr-26
A4: ALMA LIDIA GASTELUM HERNANDEZ | B4: 38717 | E4: 28 | F4: 2 | G4: 03-04-ABR | H4: 0.5 | I4: 46126 | AP4: =F4+H4+J4+L4+N4+P4+R4+T4+V4+X4+Z4+AB4+AD4+AF4+AH4+AJ4+AL4+AN4 -> 2.5 | AQ4: =C4+D4+E4-AP4 -> 25.5
A5: HILDA BEATRIZ BELTRAN LOPEZ | B5: 41276 | E5: 24 | F5: 0.5 | G5: 46083 | H5: 0.5 | I5: 46084 | J5: 2 | K5: 03-04-ABR | AP5: =F5+H5+J5+L5+N5+P5+R5+T5+V5+X5+Z5+AB5+AD5+AF5+AH5+AJ5+AL5+AN5 -> 3 | AQ5: =C5+D5+E5-AP5 -> 21
A6: ANA MARIA SUAREZ PALOMARES | B6: 42247 | D6: 22 | F6: 0.5 | G6: 45887 | H6: 0.5 | I6: 45918 | J6: 0.5 | K6: 45946 | L6: 1 | M6: 45976 | N6: 0.5 | O6: 45979 | P6: 0.5 | Q6: 46008 | R6: 1 | S6: 46034 | T6: 0.5 | U6: 46072 | V6: 1 | W6: 46053 | X6: 1 | Y6: 46073 | Z6: 1 | AA6: 46076 | AB6: 0.5 | AC6: 46093 | AD6: 2 | AE6: 03-04-ABR | AF6: 0.5 | AG6: 46120 | AP6: =F6+H6+J6+L6+N6+P6+R6+T6+V6+X6+Z6+AB6+AD6+AF6+AH6+AJ6+AL6+AN6 -> 11 | AQ6: =C6+D6+E6-AP6 -> 11
A7: MISAEL VELAZQUEZ GUERRERO | B7: 41730 | E7: 24 | F7: 4 | G7: DEL 19 AL 23 FEB | H7: 1 | I7: 46100 | J7: 2 | K7: 03-04-ABR | AP7: =F7+H7+J7+L7+N7+P7+R7+T7+V7+X7+Z7+AB7+AD7+AF7+AH7+AJ7+AL7+AN7 -> 7 | AQ7: =C7+D7+E7-AP7 -> 17
A8: MARIA MAGDALENA GARCIA LEON | B8: 42633 | D8: 22 | F8: 18 | G8: 01 AL 21 AGO | H8: 0.5 | I8: 45960 | J8: 1 | K8: 46063 | L8: 0.5 | M8: 46079 | N8: 1 | O8: 46115 | AP8: =F8+H8+J8+L8+N8+P8+R8+T8+V8+X8+Z8+AB8+AD8+AF8+AH8+AJ8+AL8+AN8 -> 21 | AQ8: =C8+D8+E8-AP8 -> 1
A9: ALICIA ISABEL SICAIROS AGUIRRE | B9: 44771 | E9: 18 | F9: 3 | G9: DEL 06 AL 09 MAR | H9: 1 | I9: 46116 | AP9: =F9+H9+J9+L9+N9+P9+R9+T9+V9+X9+Z9+AB9+AD9+AF9+AH9+AJ9+AL9+AN9 -> 4 | AQ9: =C9+D9+E9-AP9 -> 14
A10: MARIA CRISTINA BARRAZA VIZCARRA | B10: 42646 | D10: 22 | F10: 2 | G10: 26-27-NOV | H10: 3 | I10: 08-09-10-DIC | J10: 3 | K10: 15-16-17-DIC | L10: 2 | M10: 03-04-ABR | AP10: =F10+H10+J10+L10+N10+P10+R10+T10+V10+X10+Z10+AB10+AD10+AF10+AH10+AJ10+AL10+AN10 -> 10 | AQ10: =C10+D10+E10-AP10 -> 12
A11: AMERICA NATHALY VEGA GONZALEZ | B11: 43381 | D11: 22 | F11: 6 | G11: 05 al 10 ENE | H11: 1 | I11: 46069 | J11: 0.5 | K11: 46084 | L11: 1 | M11: 46088 | N11: 1 | O11: 46115 | AP11: =F11+H11+J11+L11+N11+P11+R11+T11+V11+X11+Z11+AB11+AD11+AF11+AH11+AJ11+AL11+AN11 -> 9.5 | AQ11: =C11+D11+E11-AP11 -> 12.5
A12: YUKIE LIZETH PACHECO RAMIREZ | B12: 43850 | E12: 22 | F12: 13 | G12: 25 MAR AL 08 ABR | AP12: =F12+H12+J12+L12+N12+P12+R12+T12+V12+X12+Z12+AB12+AD12+AF12+AH12+AJ12+AL12+AN12 -> 13 | AQ12: =C12+D12+E12-AP12 -> 9
A13: KIARA BELEN MORENO AGUIRRE | B13: 45941 | E13: 12 | AP13: =F13+H13+J13+L13+N13+P13+R13+T13+V13+X13+Z13+AB13+AD13+AF13+AH13+AJ13+AL13+AN13 -> 0 | AQ13: =C13+D13+E13-AP13 -> 12
A14: JOSE VALDEMAR CORVERA CARDENAS | B14: 44669 | E14: 18 | F14: 1 | G14: 46008 | H14: 1 | I14: 46095 | J14: 1 | K14: 46102 | AP14: =F14+H14+J14+L14+N14+P14+R14+T14+V14+X14+Z14+AB14+AD14+AF14+AH14+AJ14+AL14+AN14 -> 3 | AQ14: =C14+D14+E14-AP14 -> 15
A15: JESUS ALBERTO MORGAN CHAVEZ | B15: 45463 | D15: 12 | E15: 14 | F15: 2 | G15: 18-19-ABR | H15: 1 | I15: 45825 | J15: 0.5 | K15: 45840 | L15: 0.5 | M15: 45841 | N15: 3 | O15: 05-07-08-JUL | P15: 1 | Q15: 45917 | R15: 1 | S15: 46008 | T15: 1 | U15: 46051 | V15: 0.5 | W15: 46069 | X15: 0.5 | Y15: 46094 | Z15: 2 | AA15: 03-04-ABR | AP15: =F15+H15+J15+L15+N15+P15+R15+T15+V15+X15+Z15+AB15+AD15+AF15+AH15+AJ15+AL15+AN15 -> 13 | AQ15: =C15+D15+E15-AP15 -> 13
A16: GRECIA CARRANZA MARTINEZ | B16: 45827 | E16: 12 | F16: 1 | G16: 45919 | H16: 2 | I16: 03-04-ABR | AP16: =F16+H16+J16+L16+N16+P16+R16+T16+V16+X16+Z16+AB16+AD16+AF16+AH16+AJ16+AL16+AN16 -> 3 | AQ16: =C16+D16+E16-AP16 -> 9
A17: JUAN CARLOS PACHECO PEREZ | B17: 44700 | D17: 16 | F17: 1 | G17: 45756 | H17: 1 | I17: 45794 | J17: 1 | K17: 45838 | L17: 1 | M17: 45847 | N17: 1 | O17: 45871 | P17: 1 | Q17: 45926 | R17: 2 | S17: 25-27-OCT | T17: 1 | U17: 45975 | V17: 1 | W17: 46000 | X17: 1 | Y17: 46038 | Z17: 4 | AA17: DEL 25 AL 28 FEB | AB17: 1 | AC17: 46083 | AP17: =F17+H17+J17+L17+N17+P17+R17+T17+V17+X17+Z17+AB17+AD17+AF17+AH17+AJ17+AL17+AN17 -> 16 | AQ17: =C17+D17+E17-AP17 -> 0
A18: BRAYAN URIEL ANGULO RAMIREZ | B18: 44805 | D18: 16 | F18: 1 | G18: 45687 | H18: 1 | I18: 45891 | J18: 1 | K18: 45958 | L18: 3 | M18: 31 OCT AL 03 NOV | N18: 0.5 | O18: 45986 | P18: 1 | Q18: 46031 | R18: 0.5 | S18: 46043 | T18: 1 | U18: 46053 | V18: 1 | W18: 46088 | X18: 1 | Y18: 46109 | AP18: =F18+H18+J18+L18+N18+P18+R18+T18+V18+X18+Z18+AB18+AD18+AF18+AH18+AJ18+AL18+AN18 -> 11 | AQ18: =C18+D18+E18-AP18 -> 5
A19: LUIS ANGEL ABITIA CASTRO | B19: 46048 | F19: 1 | G19: 46116 | AP19: =F19+H19+J19+L19+N19+P19+R19+T19+V19+X19+Z19+AB19+AD19+AF19+AH19+AJ19+AL19+AN19 -> 1 | AQ19: =C19+D19+E19-AP19 -> -1
A20: JOSE GUADALUPE GARCIA CANCHOLA | B20: 43913 | E20: 22 | AP20: =F20+H20+J20+L20+N20+P20+R20+T20+V20+X20+Z20+AB20+AD20+AF20+AH20+AJ20+AL20+AN20 -> 0 | AQ20: =C20+D20+E20-AP20 -> 22
A21: ANGEL GERARDO LOPEZ FLORES | B21: 44277 | E21: 20 | F21: 1 | G21: 46024 | H21: 1 | I21: 46053 | J21: 1 | K21: 46098 | L21: 8 | M21: 27 MAR AL 04 ABR | AP21: =F21+H21+J21+L21+N21+P21+R21+T21+V21+X21+Z21+AB21+AD21+AF21+AH21+AJ21+AL21+AN21 -> 11 | AQ21: =C21+D21+E21-AP21 -> 9
A22: LLUVIA DE JESUS ROMERO SARABIA | B22: 44293 | D22: 18 | E22: 20 | F22: 1 | G22: 46093 | H22: 2 | I22: 18-19-ABR | J22: 1 | K22: 45782 | L22: 1 | M22: 45839 | N22: 1 | O22: 45859 | P22: 2 | Q22: 01-02-SEP | R22: 1 | S22: 45964 | T22: 1 | U22: 46042 | V22: 8 | W22: 30 MAR AL 07 ABR | X22: 4 | Y22: 08 AL 11 ABR | AP22: =F22+H22+J22+L22+N22+P22+R22+T22+V22+X22+Z22+AB22+AD22+AF22+AH22+AJ22+AL22+AN22 -> 22 | AQ22: =C22+D22+E22-AP22 -> 16
A23: JORGE ENRIQUE ARELLANES CHAVEZ | B23: 44805 | D23: 16 | F23: 1 | G23: 46115 | H23: 6 | I23: 13 AL 18 ABR | AP23: =F23+H23+J23+L23+N23+P23+R23+T23+V23+X23+Z23+AB23+AD23+AF23+AH23+AJ23+AL23+AN23 -> 7 | AQ23: =C23+D23+E23-AP23 -> 9
A24: ANTONY MEDRANO LOPEZ | B24: 44866 | C24: 14 | D24: 16 | F24: 1 | G24: 45847 | H24: 1 | I24: 45880 | J24: 1 | K24: 45881 | L24: 2 | M24: 05-06-SEP | N24: 2 | O24: 12-13-SEP | P24: 2 | Q24: 29-30-SEP | R24: 1 | S24: 45931 | T24: 1 | U24: 45951 | V24: 1 | W24: 45969 | X24: 1 | Y24: 45992 | Z24: 1 | AA24: 46057 | AB24: 1 | AC24: 46078 | AD24: 1 | AE24: 46080 | AF24: 1 | AG24: 46083 | AH24: 1 | AI24: 46092 | AJ24: 1 | AK24: 46100 | AL24: 3 | AM24: 03-04-06-ABR | AP24: =F24+H24+J24+L24+N24+P24+R24+T24+V24+X24+Z24+AB24+AD24+AF24+AH24+AJ24+AL24+AN24 -> 22 | AQ24: =C24+D24+E24-AP24 -> 8
A25: ELISA GUADALUPE GARCIA GONZALEZ | B25: 45185 | D25: 14 | F25: 1 | G25: 45960 | H25: 1 | I25: 45967 | J25: 1 | K25: 45969 | L25: 1 | M25: 46039 | N25: 1 | O25: 46093 | P25: 1 | Q25: 46102 | R25: 2 | S25: 03-04-ABR | T25: 1 | U25: 46121 | AP25: =F25+H25+J25+L25+N25+P25+R25+T25+V25+X25+Z25+AB25+AD25+AF25+AH25+AJ25+AL25+AN25 -> 9 | AQ25: =C25+D25+E25-AP25 -> 5
A26: MARIA FERNANDA RODRIGUEZ ARMENTA | B26: 45451 | D26: 12 | F26: 2 | G26: 18-19-ABR | H26: 1 | I26: 45853 | J26: 4 | K26: 06 AL 09 AGO | L26: 1 | M26: 45883 | N26: 1 | O26: 45952 | P26: 1 | Q26: 46031 | R26: 1 | S26: 46080 | T26: 1 | U26: 46115 | AP26: =F26+H26+J26+L26+N26+P26+R26+T26+V26+X26+Z26+AB26+AD26+AF26+AH26+AJ26+AL26+AN26 -> 12 | AQ26: =C26+D26+E26-AP26 -> 0
A27: CLAUDIA LIZBETH JUAREZ LOPEZ | B27: 45593 | D27: 12 | F27: 2 | G27: 18-19-ABR | H27: 1 | I27: 45869 | J27: 1 | K27: 45945 | L27: 1 | M27: 45972 | N27: 1 | O27: 45992 | P27: 1 | Q27: 46034 | R27: 3 | S27: 02-03-04-ABR | AP27: =F27+H27+J27+L27+N27+P27+R27+T27+V27+X27+Z27+AB27+AD27+AF27+AH27+AJ27+AL27+AN27 -> 10 | AQ27: =C27+D27+E27-AP27 -> 2
A28: JESUS EDUARDO BELTRAN LOPEZ | B28: 45622 | D28: 12 | F28: 2 | G28: 18-19-ABR | H28: 1 | I28: 45773 | J28: 0.5 | K28: 45786 | L28: 0.5 | M28: 45828 | N28: 1 | O28: 45908 | P28: 2 | Q28: 21-23-MAR | R28: 3 | S28: 02-03-04-ABR | AP28: =F28+H28+J28+L28+N28+P28+R28+T28+V28+X28+Z28+AB28+AD28+AF28+AH28+AJ28+AL28+AN28 -> 10 | AQ28: =C28+D28+E28-AP28 -> 2
A29: OSCAR VICENTE VALDEZ BURGUEÑO | B29: 42627 | D29: 22 | AP29: =F29+H29+J29+L29+N29+P29+R29+T29+V29+X29+Z29+AB29+AD29+AF29+AH29+AJ29+AL29+AN29 -> 0 | AQ29: =C29+D29+E29-AP29 -> 22
A30: ANTONIO NUÑEZ RAMOS | B30: 44957 | E30: 16 | AP30: =F30+H30+J30+L30+N30+P30+R30+T30+V30+X30+Z30+AB30+AD30+AF30+AH30+AJ30+AL30+AN30 -> 0 | AQ30: =C30+D30+E30-AP30 -> 16
A31: MARIO ALBERTO OCHOA CASTAÑEDA | B31: 45549 | E31: 14 | AP31: =F31+H31+J31+L31+N31+P31+R31+T31+V31+X31+Z31+AB31+AD31+AF31+AH31+AJ31+AL31+AN31 -> 0 | AQ31: =C31+D31+E31-AP31 -> 14
A32: ELLIOT CHRISTOPHER REYES BERNAL | B32: 45936 | E32: 12 | AP32: =F32+H32+J32+L32+N32+P32+R32+T32+V32+X32+Z32+AB32+AD32+AF32+AH32+AJ32+AL32+AN32 -> 0 | AQ32: =C32+D32+E32-AP32 -> 12
A33: JANETH JOSEFINA GONZALEZ ROSALES | B33: 44608 | E33: 18 | F33: 1 | G33: 46008 | H33: 1 | I33: 46018 | J33: 1 | K33: 46078 | L33: 0.5 | M33: 46084 | N33: 1 | O33: 46101 | P33: 2 | Q33: 03-04-ABR | AP33: =F33+H33+J33+L33+N33+P33+R33+T33+V33+X33+Z33+AB33+AD33+AF33+AH33+AJ33+AL33+AN33 -> 6.5 | AQ33: =C33+D33+E33-AP33 -> 11.5
A34: JHENIFER BARRAZA LOPEZ | B34: 43481 | E34: 22 | F34: 1 | G34: 46044 | H34: 1 | I34: 46050 | J34: 0.5 | K34: 46077 | AP34: =F34+H34+J34+L34+N34+P34+R34+T34+V34+X34+Z34+AB34+AD34+AF34+AH34+AJ34+AL34+AN34 -> 2.5 | AQ34: =C34+D34+E34-AP34 -> 19.5
A35: EMILIA LEAL ROMAN | B35: 45279 | D35: 14 | F35: 1 | G35: 46036 | H35: 1 | I35: 46051 | J35: 1 | K35: 46074 | AP35: =F35+H35+J35+L35+N35+P35+R35+T35+V35+X35+Z35+AB35+AD35+AF35+AH35+AJ35+AL35+AN35 -> 3 | AQ35: =C35+D35+E35-AP35 -> 11
A36: LAURA RAMIREZ SANTIAGO | B36: 45446 | E36: 14 | F36: 0.5 | G36: 46284 | H36: 0.5 | I36: 46052 | AP36: =F36+H36+J36+L36+N36+P36+R36+T36+V36+X36+Z36+AB36+AD36+AF36+AH36+AJ36+AL36+AN36 -> 1 | AQ36: =C36+D36+E36-AP36 -> 13
A37: BRYANDA GISSEL BELTRAN FELIX | B37: 45623 | D37: 12 | F37: 6 | G37: 23 AL 28 MAR | AP37: =F37+H37+J37+L37+N37+P37+R37+T37+V37+X37+Z37+AB37+AD37+AF37+AH37+AJ37+AL37+AN37 -> 6 | AQ37: =C37+D37+E37-AP37 -> 6
A38: MARCO JESUS BURGUEÑO GAXIOLA | B38: 45631 | D38: 12 | F38: 2 | G38: 16-17-FEB | AP38: =F38+H38+J38+L38+N38+P38+R38+T38+V38+X38+Z38+AB38+AD38+AF38+AH38+AJ38+AL38+AN38 -> 2 | AQ38: =C38+D38+E38-AP38 -> 10
A39: LUIS ANGEL CHAVEZ TORRECILLAS | B39: 45848 | E39: 12 | F39: 1 | G39: 46108 | AP39: =F39+H39+J39+L39+N39+P39+R39+T39+V39+X39+Z39+AB39+AD39+AF39+AH39+AJ39+AL39+AN39 -> 1 | AQ39: =C39+D39+E39-AP39 -> 11
A40: JUAN ANTONIO IRIARTE LEON | B40: 40571 | E40: 24 | AP40: =F40+H40+J40+L40+N40+P40+R40+T40+V40+X40+Z40+AB40+AD40+AF40+AH40+AJ40+AL40+AN40 -> 0 | AQ40: =C40+D40+E40-AP40 -> 24
...
